[32m2024-09-23 15:35:34 +0200[0m - dagster - [34mDEBUG[0m - __ASSET_JOB - 01a5b575-7bd0-4df0-9124-6f1a4b921e73 - 50072 - LOGS_CAPTURED - Started capturing logs in process (pid: 50072).
[32m2024-09-23 15:35:34 +0200[0m - dagster - [34mDEBUG[0m - __ASSET_JOB - 01a5b575-7bd0-4df0-9124-6f1a4b921e73 - 50072 - stg_films - STEP_START - Started execution of step "stg_films".
[32m2024-09-23 15:37:11 +0200[0m - dagster - [34mERROR[0m - [31m__ASSET_JOB - 01a5b575-7bd0-4df0-9124-6f1a4b921e73 - 50072 - stg_films - STEP_FAILURE - Execution of step "stg_films" failed.

dagster._core.errors.DagsterExecutionStepExecutionError: Error occurred while executing op "stg_films"::

json.decoder.JSONDecodeError: Expecting value: line 1 column 1 (char 0)

Stack Trace:
  File "/home/robgriffin247/.cache/pypoetry/virtualenvs/swapy-UjXh_wtJ-py3.10/lib/python3.10/site-packages/dagster/_core/execution/plan/utils.py", line 54, in op_execution_error_boundary
    yield
  File "/home/robgriffin247/.cache/pypoetry/virtualenvs/swapy-UjXh_wtJ-py3.10/lib/python3.10/site-packages/dagster/_utils/__init__.py", line 468, in iterate_with_context
    next_output = next(iterator)
  File "/home/robgriffin247/.cache/pypoetry/virtualenvs/swapy-UjXh_wtJ-py3.10/lib/python3.10/site-packages/dagster/_core/execution/plan/compute_generator.py", line 141, in _coerce_op_compute_fn_to_iterator
    result = invoke_compute_fn(
  File "/home/robgriffin247/.cache/pypoetry/virtualenvs/swapy-UjXh_wtJ-py3.10/lib/python3.10/site-packages/dagster/_core/execution/plan/compute_generator.py", line 129, in invoke_compute_fn
    return fn(context, **args_to_pass) if context_arg_provided else fn(**args_to_pass)
  File "/mnt/c/Users/robgri/Documents/git_personal/swapy/dags/assets/stg_films.py", line 8, in stg_films
    api_wan("films")
  File "/mnt/c/Users/robgri/Documents/git_personal/swapy/api_wan/api_wan.py", line 16, in api_wan
    response_json = response.json()
  File "/home/robgriffin247/.cache/pypoetry/virtualenvs/swapy-UjXh_wtJ-py3.10/lib/python3.10/site-packages/httpx/_models.py", line 764, in json
    return jsonlib.loads(self.content, **kwargs)
  File "/usr/lib/python3.10/json/__init__.py", line 346, in loads
    return _default_decoder.decode(s)
  File "/usr/lib/python3.10/json/decoder.py", line 337, in decode
    obj, end = self.raw_decode(s, idx=_w(s, 0).end())
  File "/usr/lib/python3.10/json/decoder.py", line 355, in raw_decode
    raise JSONDecodeError("Expecting value", s, err.value) from None

The above exception occurred during handling of the following exception:
StopIteration: 0

Stack Trace:
  File "/usr/lib/python3.10/json/decoder.py", line 353, in raw_decode
    obj, end = self.scan_once(s, idx)
[0m
