[32m2024-09-23 15:33:23 +0200[0m - dagster - [34mDEBUG[0m - __ASSET_JOB - 1d0021bc-4ff3-469f-925a-5533409599e6 - 45674 - LOGS_CAPTURED - Started capturing logs in process (pid: 45674).
[32m2024-09-23 15:33:24 +0200[0m - dagster - [34mDEBUG[0m - __ASSET_JOB - 1d0021bc-4ff3-469f-925a-5533409599e6 - 45674 - stg_planets - STEP_START - Started execution of step "stg_planets".
[32m2024-09-23 15:34:54 +0200[0m - dagster - [34mERROR[0m - [31m__ASSET_JOB - 1d0021bc-4ff3-469f-925a-5533409599e6 - 45674 - stg_planets - STEP_FAILURE - Execution of step "stg_planets" failed.

dagster._core.errors.DagsterExecutionStepExecutionError: Error occurred while executing op "stg_planets"::

httpx.ConnectTimeout: timed out

Stack Trace:
  File "/home/robgriffin247/.cache/pypoetry/virtualenvs/swapy-UjXh_wtJ-py3.10/lib/python3.10/site-packages/dagster/_core/execution/plan/utils.py", line 54, in op_execution_error_boundary
    yield
  File "/home/robgriffin247/.cache/pypoetry/virtualenvs/swapy-UjXh_wtJ-py3.10/lib/python3.10/site-packages/dagster/_utils/__init__.py", line 468, in iterate_with_context
    next_output = next(iterator)
  File "/home/robgriffin247/.cache/pypoetry/virtualenvs/swapy-UjXh_wtJ-py3.10/lib/python3.10/site-packages/dagster/_core/execution/plan/compute_generator.py", line 141, in _coerce_op_compute_fn_to_iterator
    result = invoke_compute_fn(
  File "/home/robgriffin247/.cache/pypoetry/virtualenvs/swapy-UjXh_wtJ-py3.10/lib/python3.10/site-packages/dagster/_core/execution/plan/compute_generator.py", line 129, in invoke_compute_fn
    return fn(context, **args_to_pass) if context_arg_provided else fn(**args_to_pass)
  File "/mnt/c/Users/robgri/Documents/git_personal/swapy/dags/assets/stg_planets.py", line 8, in stg_planets
    api_wan("planets")
  File "/mnt/c/Users/robgri/Documents/git_personal/swapy/api_wan/api_wan.py", line 14, in api_wan
    response = httpx.get(url, timeout=90)
  File "/home/robgriffin247/.cache/pypoetry/virtualenvs/swapy-UjXh_wtJ-py3.10/lib/python3.10/site-packages/httpx/_api.py", line 198, in get
    return request(
  File "/home/robgriffin247/.cache/pypoetry/virtualenvs/swapy-UjXh_wtJ-py3.10/lib/python3.10/site-packages/httpx/_api.py", line 106, in request
    return client.request(
  File "/home/robgriffin247/.cache/pypoetry/virtualenvs/swapy-UjXh_wtJ-py3.10/lib/python3.10/site-packages/httpx/_client.py", line 827, in request
    return self.send(request, auth=auth, follow_redirects=follow_redirects)
  File "/home/robgriffin247/.cache/pypoetry/virtualenvs/swapy-UjXh_wtJ-py3.10/lib/python3.10/site-packages/httpx/_client.py", line 914, in send
    response = self._send_handling_auth(
  File "/home/robgriffin247/.cache/pypoetry/virtualenvs/swapy-UjXh_wtJ-py3.10/lib/python3.10/site-packages/httpx/_client.py", line 942, in _send_handling_auth
    response = self._send_handling_redirects(
  File "/home/robgriffin247/.cache/pypoetry/virtualenvs/swapy-UjXh_wtJ-py3.10/lib/python3.10/site-packages/httpx/_client.py", line 979, in _send_handling_redirects
    response = self._send_single_request(request)
  File "/home/robgriffin247/.cache/pypoetry/virtualenvs/swapy-UjXh_wtJ-py3.10/lib/python3.10/site-packages/httpx/_client.py", line 1015, in _send_single_request
    response = transport.handle_request(request)
  File "/home/robgriffin247/.cache/pypoetry/virtualenvs/swapy-UjXh_wtJ-py3.10/lib/python3.10/site-packages/httpx/_transports/default.py", line 232, in handle_request
    with map_httpcore_exceptions():
  File "/usr/lib/python3.10/contextlib.py", line 153, in __exit__
    self.gen.throw(typ, value, traceback)
  File "/home/robgriffin247/.cache/pypoetry/virtualenvs/swapy-UjXh_wtJ-py3.10/lib/python3.10/site-packages/httpx/_transports/default.py", line 86, in map_httpcore_exceptions
    raise mapped_exc(message) from exc

The above exception was caused by the following exception:
httpcore.ConnectTimeout: timed out

Stack Trace:
  File "/home/robgriffin247/.cache/pypoetry/virtualenvs/swapy-UjXh_wtJ-py3.10/lib/python3.10/site-packages/httpx/_transports/default.py", line 69, in map_httpcore_exceptions
    yield
  File "/home/robgriffin247/.cache/pypoetry/virtualenvs/swapy-UjXh_wtJ-py3.10/lib/python3.10/site-packages/httpx/_transports/default.py", line 233, in handle_request
    resp = self._pool.handle_request(req)
  File "/home/robgriffin247/.cache/pypoetry/virtualenvs/swapy-UjXh_wtJ-py3.10/lib/python3.10/site-packages/httpcore/_sync/connection_pool.py", line 216, in handle_request
    raise exc from None
  File "/home/robgriffin247/.cache/pypoetry/virtualenvs/swapy-UjXh_wtJ-py3.10/lib/python3.10/site-packages/httpcore/_sync/connection_pool.py", line 196, in handle_request
    response = connection.handle_request(
  File "/home/robgriffin247/.cache/pypoetry/virtualenvs/swapy-UjXh_wtJ-py3.10/lib/python3.10/site-packages/httpcore/_sync/connection.py", line 99, in handle_request
    raise exc
  File "/home/robgriffin247/.cache/pypoetry/virtualenvs/swapy-UjXh_wtJ-py3.10/lib/python3.10/site-packages/httpcore/_sync/connection.py", line 76, in handle_request
    stream = self._connect(request)
  File "/home/robgriffin247/.cache/pypoetry/virtualenvs/swapy-UjXh_wtJ-py3.10/lib/python3.10/site-packages/httpcore/_sync/connection.py", line 122, in _connect
    stream = self._network_backend.connect_tcp(**kwargs)
  File "/home/robgriffin247/.cache/pypoetry/virtualenvs/swapy-UjXh_wtJ-py3.10/lib/python3.10/site-packages/httpcore/_backends/sync.py", line 205, in connect_tcp
    with map_exceptions(exc_map):
  File "/usr/lib/python3.10/contextlib.py", line 153, in __exit__
    self.gen.throw(typ, value, traceback)
  File "/home/robgriffin247/.cache/pypoetry/virtualenvs/swapy-UjXh_wtJ-py3.10/lib/python3.10/site-packages/httpcore/_exceptions.py", line 14, in map_exceptions
    raise to_exc(exc) from exc

The above exception occurred during handling of the following exception:
TimeoutError: timed out

Stack Trace:
  File "/home/robgriffin247/.cache/pypoetry/virtualenvs/swapy-UjXh_wtJ-py3.10/lib/python3.10/site-packages/httpcore/_exceptions.py", line 10, in map_exceptions
    yield
  File "/home/robgriffin247/.cache/pypoetry/virtualenvs/swapy-UjXh_wtJ-py3.10/lib/python3.10/site-packages/httpcore/_backends/sync.py", line 206, in connect_tcp
    sock = socket.create_connection(
  File "/usr/lib/python3.10/socket.py", line 845, in create_connection
    raise err
  File "/usr/lib/python3.10/socket.py", line 833, in create_connection
    sock.connect(sa)
[0m
